#VRML_SIM R2021b utf8
WorldInfo {
  basicTimeStep 10
  inkEvaporation 4
  coordinateSystem "NUE"
  contactProperties [
    ContactProperties {
      coulombFriction [
        1.5
      ]
      bounce 0.1
    }
    ContactProperties {
      material1 "wall"
      coulombFriction [
        0
      ]
    }
  ]
}
Viewpoint {
  orientation -0.061234836208193866 -0.9893856386037934 -0.13178145908707906 2.2341203466303425
  position -1.0061554522301517 3.002321301560927 -13.482384614971723
  follow "robot"
}
TexturedBackground {
}
TexturedBackgroundLight {
}
RectangleArena {
  floorSize 21 30
  wallHeight 0.2
}
WoodenPallet {
  translation 0.389824 1.77636e-15 1.84052
  rotation 0 1 0 2.04989
  size 0.8 0.1 1.2
}
WoodenPallet {
  translation -0.88886 0 1.77535
  rotation 0 -1 0 0.541925
  name "wooden pallet(1)"
  size 0.8 0.1 1.2
}
WoodenPallet {
  translation -1.62495 -4.00791e-14 -3.92604
  rotation 0 1 0 1.13882
  name "wooden pallet(2)"
  size 0.8 0.1 1.2
}
WoodenPallet {
  translation -1.08718 0 3.61611
  name "wooden pallet(3)"
  size 0.8 0.1 1.2
}
WoodenBox {
  translation 0.0992687 0.25 -1.74271
  size 3 0.1 0.6
}
WoodenBox {
  translation 0.100739 0.15 -1.2509
  name "wooden box(4)"
  size 3 0.1 0.6
}
WoodenBox {
  translation 0.100739 0.15 -2.2309
  name "wooden box(3)"
  size 3 0.1 0.6
}
WoodenBox {
  translation 0.0357807 0.05 -2.71663
  name "wooden box(1)"
  size 3 0.1 0.6
}
WoodenBox {
  translation 0.0357807 0.05 -0.81663
  name "wooden box(5)"
  size 3 0.1 0.6
}
WoodenBox {
  translation 0 0 0
  name "wooden box(2)"
  size 3 0.1 0.6
}
Robot {
  translation 2.18677 0.73997 -10.3103
  rotation -0.564266168453227 0.7010808965241739 -0.43599227936739315 8.618183308802926e-18
  children [
    Camera {
      translation 0 0.1 0.4
      rotation 0 -1 0 3.14
      children [
        Transform {
          children [
            Shape {
              appearance PBRAppearance {
              }
              geometry Cylinder {
                height 0.1
                radius 0.05
              }
            }
          ]
        }
      ]
    }
    Accelerometer {
      translation 0 0.16 0
      children [
        DEF ACC Shape {
          appearance PBRAppearance {
          }
          geometry Box {
            size 0.1 0.1 0.1
          }
        }
      ]
      boundingObject USE ACC
      physics Physics {
        density -1
        mass 0.2
      }
    }
    InertialUnit {
      translation 0 0.003 -0.045
      children [
        DEF IMU_SHAPE Shape {
          appearance PBRAppearance {
          }
          geometry Box {
            size 0.01 0.01 0.01
          }
        }
      ]
    }
    DEF BODY_SHAPE Shape {
      appearance PBRAppearance {
        baseColor 0.333333 1 1
        roughness 1
        metalness 0
      }
      geometry Box {
        size 0.4 0.2 0.8
      }
    }
    DEF LB_LEG_POS Transform {
      translation 0.24 0 -0.3
      children [
        DEF LB_LEG_L0 HingeJoint {
          jointParameters HingeJointParameters {
            position 1.1308973183689637e-19
            axis 0 0 1
            minStop -0.8
            maxStop 0.8
          }
          device [
            PositionSensor {
              name "LBL0_position sensor"
            }
            RotationalMotor {
              name "LBL0_rotational motor"
              maxTorque 2000
            }
          ]
          endPoint Solid {
            translation -2.928176983662999e-07 0.0003215887949651337 -7.533677867765906e-06
            rotation -0.9999999999999267 -2.602580857645386e-07 2.8077944576118515e-07 1.5708380155486839
            children [
              DEF L0_SHAPE Shape {
                appearance PBRAppearance {
                }
                geometry Cylinder {
                  height 0.05
                  radius 0.02
                }
              }
              Transform {
                rotation 1 0 0 1.5707996938995747
                children [
                  DEF LB_LEG_L1 HingeJoint {
                    jointParameters HingeJointParameters {
                      position 0.6
                      minStop 0.2
                      maxStop 1.5
                    }
                    device [
                      PositionSensor {
                        name "LBL1_position sensor"
                      }
                      RotationalMotor {
                        name "LBL1_rotational motor"
                        maxTorque 2000
                      }
                    ]
                    endPoint Solid {
                      translation -4.16768093269792e-06 -0.16499577714019598 -0.1129356726573423
                      rotation 0.9999999999965185 8.83695621395654e-07 -2.4863725004772584e-06 0.6000203206673796
                      children [
                        DEF LEG_0_SHAPE Shape {
                          appearance PBRAppearance {
                            baseColor 1 1 0
                            roughness 1
                            metalness 0
                          }
                          geometry Capsule {
                            height 0.4
                            radius 0.02
                          }
                        }
                        Transform {
                          translation 0 -0.2 0
                          children [
                            DEF LB_LEG_L2 HingeJoint {
                              jointParameters HingeJointParameters {
                                position -1.28
                                minStop -2.2
                                maxStop -0.2
                              }
                              device [
                                PositionSensor {
                                  name "LBL2_position sensor"
                                }
                                RotationalMotor {
                                  name "LBL2_rotational motor"
                                  maxTorque 2000
                                }
                              ]
                              endPoint Solid {
                                translation 2.7755575615632833e-17 -0.05734304192641654 0.1916031720579279
                                rotation -1 0 0 1.2799999999999998
                                children [
                                  DEF LEG_1_SHAPE Shape {
                                    appearance PBRAppearance {
                                    }
                                    geometry Capsule {
                                      height 0.4
                                      radius 0.02
                                    }
                                  }
                                  TouchSensor {
                                    translation 1.3145040611561853e-13 -0.2000000773008411 -6.040024705389335e-08
                                    rotation -0.9999999999806732 -4.76837158195644e-07 -6.198883056543372e-06 -1.1102230246425746e-16
                                    children [
                                      DEF TC_SENSOR Shape {
                                        appearance PBRAppearance {
                                        }
                                        geometry Sphere {
                                          radius 0.05
                                        }
                                      }
                                    ]
                                    name "LB_touch sensor"
                                    boundingObject USE TC_SENSOR
                                    physics Physics {
                                      density -1
                                      mass 0.2
                                    }
                                  }
                                ]
                                name "XIAOTUI_LB"
                                boundingObject USE LEG_1_SHAPE
                                physics Physics {
                                  density -1
                                  mass 4
                                }
                              }
                            }
                          ]
                        }
                      ]
                      name "DATUI_LB"
                      boundingObject USE LEG_0_SHAPE
                      physics Physics {
                        density -1
                        mass 4
                        centerOfMass [
                          0 0 0
                        ]
                      }
                    }
                  }
                ]
              }
            ]
            name "GUANJIE_LB"
            boundingObject USE L0_SHAPE
            physics Physics {
            }
          }
        }
      ]
    }
    DEF LF_LEG_POS Transform {
      translation 0.24 0 0.3
      children [
        DEF LF_LEG_L0 HingeJoint {
          jointParameters HingeJointParameters {
            position 4.2997352248025267e-20
            axis 0 0 1
            minStop -0.8
            maxStop 0.8
          }
          device [
            PositionSensor {
              name "LFL0_position sensor"
            }
            RotationalMotor {
              name "LFL0_rotational motor"
              maxTorque 2000
            }
          ]
          endPoint Solid {
            translation 2.945884000626879e-07 4.37845133315349e-05 -6.263792522442862e-06
            rotation -0.9999999998969431 -1.0134092144397352e-05 1.016927041213994e-05 1.5708278592232392
            children [
              DEF L0_SHAPE Shape {
                appearance PBRAppearance {
                }
                geometry Cylinder {
                  height 0.05
                  radius 0.02
                }
              }
              Transform {
                rotation 1 0 0 1.5707996938995747
                children [
                  DEF LF_LEG_L1 HingeJoint {
                    jointParameters HingeJointParameters {
                      position 0.6
                      minStop 0.2
                      maxStop 1.5
                    }
                    device [
                      PositionSensor {
                        name "LFL1_position sensor"
                      }
                      RotationalMotor {
                        name "LFL1_rotational motor"
                        maxTorque 2000
                      }
                    ]
                    endPoint Solid {
                      translation -4.351715419098054e-06 -0.16506814147546314 -0.11293412911000851
                      rotation 0.9999999999961134 8.238634197800424e-07 -2.6634689992150658e-06 0.6000203093759043
                      children [
                        DEF LEG_0_SHAPE Shape {
                          appearance PBRAppearance {
                            baseColor 1 1 0
                            roughness 1
                            metalness 0
                          }
                          geometry Capsule {
                            height 0.4
                            radius 0.02
                          }
                        }
                        Transform {
                          translation 0 -0.2 0
                          children [
                            DEF LF_LEG_L2 HingeJoint {
                              jointParameters HingeJointParameters {
                                position -1.28
                                minStop -2.2
                                maxStop -0.2
                              }
                              device [
                                PositionSensor {
                                  name "LFL2_position sensor"
                                }
                                RotationalMotor {
                                  name "LFL2_rotational motor"
                                  maxTorque 2000
                                }
                              ]
                              endPoint Solid {
                                translation 5.551115123126537e-17 -0.05734304192641664 0.19160317205792826
                                rotation -1 0 0 1.2799999999999998
                                children [
                                  DEF LEG_1_SHAPE Shape {
                                    appearance PBRAppearance {
                                    }
                                    geometry Capsule {
                                      height 0.4
                                      radius 0.02
                                    }
                                  }
                                  TouchSensor {
                                    translation 1.314226505400029e-13 -0.20000007730084102 -6.040024708164893e-08
                                    rotation -0.9999999999971578 -1.9073486328053443e-06 1.4305114746040082e-06 -2.2204460492586435e-16
                                    children [
                                      DEF TC_SENSOR Shape {
                                        appearance PBRAppearance {
                                        }
                                        geometry Sphere {
                                          radius 0.05
                                        }
                                      }
                                    ]
                                    name "LF_touch sensor"
                                    boundingObject USE TC_SENSOR
                                    physics Physics {
                                      density -1
                                      mass 0.2
                                    }
                                  }
                                ]
                                name "XIAOTUI"
                                boundingObject USE LEG_1_SHAPE
                                physics Physics {
                                  density -1
                                  mass 4
                                }
                              }
                            }
                          ]
                        }
                      ]
                      name "DATUI"
                      boundingObject USE LEG_0_SHAPE
                      physics Physics {
                        density -1
                        mass 4
                      }
                    }
                  }
                ]
              }
            ]
            name "GUANJIE"
            boundingObject USE L0_SHAPE
            physics Physics {
            }
          }
        }
      ]
    }
    DEF RB_LEG_POS Transform {
      translation -0.24 0 -0.3
      children [
        DEF RB_LEG_L0 HingeJoint {
          jointParameters HingeJointParameters {
            position 1.1324129340792117e-19
            axis 0 0 1
            minStop -0.8
            maxStop 0.8
          }
          device [
            PositionSensor {
              name "RBL0_position sensor"
            }
            RotationalMotor {
              name "RBL0_rotational motor"
              maxTorque 2000
            }
          ]
          endPoint Solid {
            translation 4.3863095561258145e-07 0.0002692197568010545 -7.42186654179022e-06
            rotation -0.9999999999213061 8.860936338556508e-06 -8.880968534442927e-06 1.5708309725138432
            children [
              DEF L0_SHAPE Shape {
                appearance PBRAppearance {
                }
                geometry Cylinder {
                  height 0.05
                  radius 0.02
                }
              }
              Transform {
                rotation 1 0 0 1.5707996938995747
                children [
                  DEF RB_LEG_L1 HingeJoint {
                    jointParameters HingeJointParameters {
                      position 0.6
                      minStop 0.2
                      maxStop 1.5
                    }
                    device [
                      PositionSensor {
                        name "RBL1_position sensor"
                      }
                      RotationalMotor {
                        name "RBL1_rotational motor"
                        maxTorque 2000
                      }
                    ]
                    endPoint Solid {
                      translation -4.351715419125808e-06 -0.16506814147546844 -0.11293412911001176
                      rotation 0.9999999999961131 8.239031534855658e-07 -2.663597454352963e-06 0.6000203103315469
                      children [
                        DEF LEG_0_SHAPE Shape {
                          appearance PBRAppearance {
                            baseColor 1 1 0
                            roughness 1
                            metalness 0
                          }
                          geometry Capsule {
                            height 0.4
                            radius 0.02
                          }
                        }
                        Transform {
                          translation 0 -0.2 0
                          children [
                            DEF RB_LEG_L2 HingeJoint {
                              jointParameters HingeJointParameters {
                                position -1.28
                                minStop -2.2
                                maxStop -0.2
                              }
                              device [
                                PositionSensor {
                                  name "RBL2_position sensor"
                                }
                                RotationalMotor {
                                  name "RBL2_rotational motor"
                                  maxTorque 2000
                                }
                              ]
                              endPoint Solid {
                                translation 0 -0.05734304192641496 0.19160317205792612
                                rotation -1 0 0 1.2799999999999998
                                children [
                                  DEF LEG_1_SHAPE Shape {
                                    appearance PBRAppearance {
                                    }
                                    geometry Capsule {
                                      height 0.4
                                      radius 0.02
                                    }
                                  }
                                  TouchSensor {
                                    translation 1.3145040611561853e-13 -0.20000007730084096 -6.04002471094045e-08
                                    rotation -0.9999999999999227 -1.6391277313228361e-07 -3.5762786865225513e-07 -4.440892098501727e-16
                                    children [
                                      DEF TC_SENSOR Shape {
                                        appearance PBRAppearance {
                                        }
                                        geometry Sphere {
                                          radius 0.05
                                        }
                                      }
                                    ]
                                    name "RB_touch sensor"
                                    boundingObject USE TC_SENSOR
                                    physics Physics {
                                      density -1
                                      mass 0.2
                                    }
                                  }
                                ]
                                boundingObject USE LEG_1_SHAPE
                                physics Physics {
                                  density -1
                                  mass 4
                                }
                              }
                            }
                          ]
                        }
                      ]
                      boundingObject USE LEG_0_SHAPE
                      physics Physics {
                        density -1
                        mass 4
                      }
                    }
                  }
                ]
              }
            ]
            boundingObject USE L0_SHAPE
            physics Physics {
            }
          }
        }
      ]
    }
    DEF RF_LEG_POS Transform {
      translation -0.24 0 0.3
      children [
        DEF RF_LEG_L0 HingeJoint {
          jointParameters HingeJointParameters {
            position 4.3100604842605623e-20
            axis 0 0 1
            minStop -0.8
            maxStop 0.8
          }
          device [
            PositionSensor {
              name "RFL0_position sensor"
            }
            RotationalMotor {
              name "RFL0_rotational motor"
              maxTorque 2000
            }
          ]
          endPoint Solid {
            translation -3.580009655390609e-07 3.901523243865514e-05 -6.135334481793816e-06
            rotation -0.9999999998777968 -1.1071115101887702e-05 1.103796786406205e-05 1.5708276420689284
            children [
              DEF L0_SHAPE Shape {
                appearance PBRAppearance {
                }
                geometry Cylinder {
                  height 0.05
                  radius 0.02
                }
              }
              Transform {
                rotation 1 0 0 1.5707996938995747
                children [
                  DEF RF_LEG_L1 HingeJoint {
                    jointParameters HingeJointParameters {
                      position 0.6
                      minStop 0.2
                      maxStop 1.5
                    }
                    device [
                      PositionSensor {
                        name "RFL1_position sensor"
                      }
                      RotationalMotor {
                        name "RFL1_rotational motor"
                        maxTorque 2000
                      }
                    ]
                    endPoint Solid {
                      translation -4.351715419098067e-06 -0.16506814147546256 -0.11293412911000741
                      rotation 0.9999999999961131 8.239108606480146e-07 -2.66362237085193e-06 0.6000203105926765
                      children [
                        DEF LEG_0_SHAPE Shape {
                          appearance PBRAppearance {
                            baseColor 1 1 0
                            roughness 1
                            metalness 0
                          }
                          geometry Capsule {
                            height 0.4
                            radius 0.02
                          }
                        }
                        Transform {
                          translation 0 -0.2 0
                          children [
                            DEF RF_LEG_L2 HingeJoint {
                              jointParameters HingeJointParameters {
                                position -1.28
                                minStop -2.2
                                maxStop -0.2
                              }
                              device [
                                PositionSensor {
                                  name "RFL2_position sensor"
                                }
                                RotationalMotor {
                                  name "RFL2_rotational motor"
                                  maxTorque 2000
                                }
                              ]
                              endPoint Solid {
                                translation 2.775557561563266e-17 -0.057343041926416594 0.191603172057931
                                rotation -1 0 0 1.2799999999999998
                                children [
                                  DEF LEG_1_SHAPE Shape {
                                    appearance PBRAppearance {
                                    }
                                    geometry Capsule {
                                      height 0.4
                                      radius 0.02
                                    }
                                  }
                                  TouchSensor {
                                    translation 1.3145040611561853e-13 -0.20000007730084113 -6.040024708164893e-08
                                    rotation -0.9999999999990478 1.3709068298328347e-06 -1.5894571940090838e-07 -3.3306690738782627e-16
                                    children [
                                      DEF TC_SENSOR Shape {
                                        appearance PBRAppearance {
                                        }
                                        geometry Sphere {
                                          radius 0.05
                                        }
                                      }
                                    ]
                                    name "RF_touch sensor"
                                    boundingObject USE TC_SENSOR
                                    physics Physics {
                                      density -1
                                      mass 0.2
                                    }
                                  }
                                ]
                                boundingObject USE LEG_1_SHAPE
                                physics Physics {
                                  density -1
                                  mass 4
                                }
                              }
                            }
                          ]
                        }
                      ]
                      boundingObject USE LEG_0_SHAPE
                      physics Physics {
                        density -1
                        mass 4
                      }
                    }
                  }
                ]
              }
            ]
            name "solid(3)"
            boundingObject USE L0_SHAPE
            physics Physics {
            }
          }
        }
      ]
    }
  ]
  boundingObject USE BODY_SHAPE
  physics Physics {
    density -1
    mass 50
  }
  controller "my_controller"
}
DEF SLOPE_PATH Solid {
  translation -8.24 0 6.64
  children [
    DEF SLOPE_GROUP Group {
      children [
        Transform {
          translation 0 0.207058 0.772743
          rotation 1 0 0 -0.2617996938995747
          children [
            Shape {
              appearance DEF APPERANCE PBRAppearance {
                baseColor 0.929412 0.992157 1
                roughness 1
                metalness 0
              }
              geometry DEF PATH Box {
                size 1.5 0.1 2
              }
            }
          ]
        }
        Transform {
          translation 0 0.47 2.73
          children [
            Shape {
              appearance USE APPERANCE
              geometry USE PATH
            }
          ]
        }
        Transform {
          translation 0 0.210114 4.67684
          rotation -1 0 0 -0.2617996938995747
          children [
            Shape {
              appearance USE APPERANCE
              geometry USE PATH
            }
          ]
        }
      ]
    }
  ]
  name "solid(1)"
  boundingObject USE SLOPE_GROUP
}
DEF SLOPE_PATH Solid {
  translation 5.3343 -1.77636e-14 5.9582
  rotation 0 1 0 -1.5707953071795862
  children [
    DEF SLOPE_GROUP Group {
      children [
        Transform {
          translation 0 0.610201 0.563372
          rotation 1 0 0 -0.3926996938995747
          children [
            Shape {
              appearance DEF APPERANCE PBRAppearance {
                baseColor 0.929412 0.992157 1
                roughness 1
                metalness 0
              }
              geometry DEF PATH Box {
                size 1.5 0.1 5
              }
            }
          ]
        }
        Transform {
          translation 0 1.56 5.36
          children [
            Shape {
              appearance USE APPERANCE
              geometry USE PATH
            }
          ]
        }
        Transform {
          translation 0 0.598708 10.1076
          rotation -1 0 0 -0.3926996938995747
          children [
            Shape {
              appearance USE APPERANCE
              geometry USE PATH
            }
          ]
        }
      ]
    }
  ]
  name "solid(2)"
  boundingObject USE SLOPE_GROUP
}
DEF SLOPE_PATH Solid {
  translation 8.18 0 -9.24
  children [
    DEF SLOPE_GROUP Group {
      children [
        Transform {
          translation 0 0.610201 0.563372
          rotation 1 0 0 -0.26180030610042526
          children [
            Shape {
              appearance DEF APPERANCE PBRAppearance {
                baseColor 0.929412 0.992157 1
                roughness 1
                metalness 0
              }
              geometry DEF PATH Box {
                size 1.5 0.1 5
              }
            }
          ]
        }
        Transform {
          translation 0 1.25 5.44
          children [
            Shape {
              appearance USE APPERANCE
              geometry USE PATH
            }
          ]
        }
        Transform {
          translation 0 0.592256 10.3323
          rotation -1 0 0 -0.26180030610042526
          children [
            Shape {
              appearance USE APPERANCE
              geometry USE PATH
            }
          ]
        }
      ]
    }
  ]
  name "solid(4)"
  boundingObject USE SLOPE_GROUP
}
