#VRML_SIM R2021b utf8
WorldInfo {
  basicTimeStep 10
  FPS 100
  inkEvaporation 4
  coordinateSystem "NUE"
  contactProperties [
    ContactProperties {
      coulombFriction [
        1.5
      ]
      bounce 0.1
    }
    ContactProperties {
      material1 "wall"
      coulombFriction [
        0
      ]
    }
  ]
}
Viewpoint {
  orientation -0.1621392329884006 -0.9475866615981949 -0.27530054102220997 2.1017963404004854
  position -1.8786220299495011 3.8785401919720477 -12.969177639505393
  follow "robot"
}
TexturedBackground {
}
TexturedBackgroundLight {
}
RectangleArena {
  floorSize 21 30
  wallHeight 0.2
}
WoodenPallet {
  translation 0.389824 1.77636e-15 1.84052
  rotation 0 1 0 2.04989
  size 0.8 0.1 1.2
}
WoodenPallet {
  translation -0.88886 0 1.77535
  rotation 0 -1 0 0.541925
  name "wooden pallet(1)"
  size 0.8 0.1 1.2
}
WoodenPallet {
  translation -1.62495 -4.00791e-14 -3.92604
  rotation 0 1 0 1.13882
  name "wooden pallet(2)"
  size 0.8 0.1 1.2
}
WoodenPallet {
  translation -1.08718 0 3.61611
  name "wooden pallet(3)"
  size 0.8 0.1 1.2
}
WoodenBox {
  translation 0.0992687 0.25 -1.74271
  size 3 0.1 0.6
}
WoodenBox {
  translation 0.100739 0.15 -1.2509
  name "wooden box(4)"
  size 3 0.1 0.6
}
WoodenBox {
  translation 0.100739 0.15 -2.2309
  name "wooden box(3)"
  size 3 0.1 0.6
}
WoodenBox {
  translation 0.0357807 0.05 -2.71663
  name "wooden box(1)"
  size 3 0.1 0.6
}
WoodenBox {
  translation 0.0357807 0.05 -0.81663
  name "wooden box(5)"
  size 3 0.1 0.6
}
WoodenBox {
  translation 0 0 0
  name "wooden box(2)"
  size 3 0.1 0.6
}
Robot {
  translation 2.18677 0.73997 -10.3103
  rotation -0.564266168453227 0.7010808965241739 -0.43599227936739315 8.618183308802926e-18
  children [
    Accelerometer {
      translation 0 0.16 0
      children [
        DEF ACC Shape {
          appearance PBRAppearance {
          }
          geometry Box {
            size 0.1 0.1 0.1
          }
        }
      ]
      boundingObject USE ACC
      physics Physics {
        density -1
        mass 0.2
      }
    }
    InertialUnit {
      translation 0 0.003 -0.045
      children [
        DEF IMU_SHAPE Shape {
          appearance PBRAppearance {
          }
          geometry Box {
            size 0.01 0.01 0.01
          }
        }
      ]
    }
    DEF BODY_SHAPE Shape {
      appearance PBRAppearance {
        baseColor 0.333333 1 1
        roughness 1
        metalness 0
      }
      geometry Box {
        size 0.4 0.2 0.8
      }
    }
    DEF LB_LEG_POS Transform {
      translation 0.24 0 -0.3
      children [
        DEF LB_LEG_L0 HingeJoint {
          jointParameters HingeJointParameters {
            position 1.1308973183689637e-19
            axis 0 0 1
            minStop -0.8
            maxStop 0.8
          }
          device [
            PositionSensor {
              name "LBL0_position sensor"
            }
            RotationalMotor {
              name "LBL0_rotational motor"
              maxTorque 2000
            }
          ]
          endPoint Solid {
            translation 3.6248435453245515e-07 0.00032533264190659494 -9.487881820646749e-06
            rotation -0.9999999999999266 -2.6752632407210846e-07 2.7462985830270097e-07 1.5708370028241418
            children [
              DEF L0_SHAPE Shape {
                appearance PBRAppearance {
                }
                geometry Cylinder {
                  height 0.05
                  radius 0.02
                }
              }
              Transform {
                rotation 1 0 0 1.5707996938995747
                children [
                  DEF LB_LEG_L1 HingeJoint {
                    jointParameters HingeJointParameters {
                      position 0.6
                      minStop 0.2
                      maxStop 1.5
                    }
                    device [
                      PositionSensor {
                        name "LBL1_position sensor"
                      }
                      RotationalMotor {
                        name "LBL1_rotational motor"
                        maxTorque 2000
                      }
                    ]
                    endPoint Solid {
                      translation -4.16768093269781e-06 -0.16499577714019315 -0.11293567265734036
                      rotation 0.9999999999965185 8.836918420142663e-07 -2.4863618667819833e-06 0.6000203205804755
                      children [
                        DEF LEG_0_SHAPE Shape {
                          appearance PBRAppearance {
                            baseColor 1 1 0
                            roughness 1
                            metalness 0
                          }
                          geometry Capsule {
                            height 0.4
                            radius 0.02
                          }
                        }
                        Transform {
                          translation 0 -0.2 0
                          children [
                            DEF LB_LEG_L2 HingeJoint {
                              jointParameters HingeJointParameters {
                                position -1.28
                                minStop -2.2
                                maxStop -0.2
                              }
                              device [
                                PositionSensor {
                                  name "LBL2_position sensor"
                                }
                                RotationalMotor {
                                  name "LBL2_rotational motor"
                                  maxTorque 2000
                                }
                              ]
                              endPoint Solid {
                                translation 2.7755575615633634e-17 -0.05734304192641795 0.19160317205793262
                                rotation -1 0 0 1.2799999999999998
                                children [
                                  DEF LEG_1_SHAPE Shape {
                                    appearance PBRAppearance {
                                    }
                                    geometry Capsule {
                                      height 0.4
                                      radius 0.02
                                    }
                                  }
                                  TouchSensor {
                                    translation 1.3145040611561853e-13 -0.2000000773008411 -6.040024705389335e-08
                                    rotation -0.9999999999806732 -4.76837158195644e-07 -6.198883056543372e-06 -1.1102230246425746e-16
                                    children [
                                      DEF TC_SENSOR Shape {
                                        appearance PBRAppearance {
                                        }
                                        geometry Sphere {
                                          radius 0.05
                                        }
                                      }
                                    ]
                                    name "LB_touch sensor"
                                    boundingObject USE TC_SENSOR
                                    physics Physics {
                                      density -1
                                      mass 0.2
                                    }
                                  }
                                ]
                                name "XIAOTUI_LB"
                                boundingObject USE LEG_1_SHAPE
                                physics Physics {
                                  density -1
                                  mass 4
                                }
                              }
                            }
                          ]
                        }
                      ]
                      name "DATUI_LB"
                      boundingObject USE LEG_0_SHAPE
                      physics Physics {
                        density -1
                        mass 4
                        centerOfMass [
                          0 0 0
                        ]
                      }
                    }
                  }
                ]
              }
            ]
            name "GUANJIE_LB"
            boundingObject USE L0_SHAPE
            physics Physics {
            }
          }
        }
      ]
    }
    DEF LF_LEG_POS Transform {
      translation 0.24 0 0.3
      children [
        DEF LF_LEG_L0 HingeJoint {
          jointParameters HingeJointParameters {
            position 4.2997352248025267e-20
            axis 0 0 1
            minStop -0.8
            maxStop 0.8
          }
          device [
            PositionSensor {
              name "LFL0_position sensor"
            }
            RotationalMotor {
              name "LFL0_rotational motor"
              maxTorque 2000
            }
          ]
          endPoint Solid {
            translation 1.308884129525012e-06 4.4298186907765214e-05 -5.934670864959912e-06
            rotation -0.9999999998969491 -1.0150652884990987e-05 1.0152161610035006e-05 1.5708278807568152
            children [
              DEF L0_SHAPE Shape {
                appearance PBRAppearance {
                }
                geometry Cylinder {
                  height 0.05
                  radius 0.02
                }
              }
              Transform {
                rotation 1 0 0 1.5707996938995747
                children [
                  DEF LF_LEG_L1 HingeJoint {
                    jointParameters HingeJointParameters {
                      position 0.6
                      minStop 0.2
                      maxStop 1.5
                    }
                    device [
                      PositionSensor {
                        name "LFL1_position sensor"
                      }
                      RotationalMotor {
                        name "LFL1_rotational motor"
                        maxTorque 2000
                      }
                    ]
                    endPoint Solid {
                      translation -4.3517154190979385e-06 -0.16506814147546028 -0.11293412911000657
                      rotation 0.9999999999961134 8.238634198260814e-07 -2.6634689993639077e-06 0.6000203093759043
                      children [
                        DEF LEG_0_SHAPE Shape {
                          appearance PBRAppearance {
                            baseColor 1 1 0
                            roughness 1
                            metalness 0
                          }
                          geometry Capsule {
                            height 0.4
                            radius 0.02
                          }
                        }
                        Transform {
                          translation 0 -0.2 0
                          children [
                            DEF LF_LEG_L2 HingeJoint {
                              jointParameters HingeJointParameters {
                                position -1.28
                                minStop -2.2
                                maxStop -0.2
                              }
                              device [
                                PositionSensor {
                                  name "LFL2_position sensor"
                                }
                                RotationalMotor {
                                  name "LFL2_rotational motor"
                                  maxTorque 2000
                                }
                              ]
                              endPoint Solid {
                                translation 5.5511151231267e-17 -0.05734304192641809 0.1916031720579331
                                rotation -1 0 0 1.2799999999999998
                                children [
                                  DEF LEG_1_SHAPE Shape {
                                    appearance PBRAppearance {
                                    }
                                    geometry Capsule {
                                      height 0.4
                                      radius 0.02
                                    }
                                  }
                                  TouchSensor {
                                    translation 1.314226505400029e-13 -0.20000007730084102 -6.040024708164893e-08
                                    rotation -0.9999999999971578 -1.9073486328053443e-06 1.4305114746040082e-06 -2.2204460492586435e-16
                                    children [
                                      DEF TC_SENSOR Shape {
                                        appearance PBRAppearance {
                                        }
                                        geometry Sphere {
                                          radius 0.05
                                        }
                                      }
                                    ]
                                    name "LF_touch sensor"
                                    boundingObject USE TC_SENSOR
                                    physics Physics {
                                      density -1
                                      mass 0.2
                                    }
                                  }
                                ]
                                name "XIAOTUI"
                                boundingObject USE LEG_1_SHAPE
                                physics Physics {
                                  density -1
                                  mass 4
                                }
                              }
                            }
                          ]
                        }
                      ]
                      name "DATUI"
                      boundingObject USE LEG_0_SHAPE
                      physics Physics {
                        density -1
                        mass 4
                      }
                    }
                  }
                ]
              }
            ]
            name "GUANJIE"
            boundingObject USE L0_SHAPE
            physics Physics {
            }
          }
        }
      ]
    }
    DEF RB_LEG_POS Transform {
      translation -0.24 0 -0.3
      children [
        DEF RB_LEG_L0 HingeJoint {
          jointParameters HingeJointParameters {
            position 1.1324129340792117e-19
            axis 0 0 1
            minStop -0.8
            maxStop 0.8
          }
          device [
            PositionSensor {
              name "RBL0_position sensor"
            }
            RotationalMotor {
              name "RBL0_rotational motor"
              maxTorque 2000
            }
          ]
          endPoint Solid {
            translation -3.334232177021335e-07 0.00026906199872200887 -7.594799352972359e-06
            rotation -0.999999999921309 8.861113963756538e-06 -8.880470844062964e-06 1.5708310729099535
            children [
              DEF L0_SHAPE Shape {
                appearance PBRAppearance {
                }
                geometry Cylinder {
                  height 0.05
                  radius 0.02
                }
              }
              Transform {
                rotation 1 0 0 1.5707996938995747
                children [
                  DEF RB_LEG_L1 HingeJoint {
                    jointParameters HingeJointParameters {
                      position 0.6
                      minStop 0.2
                      maxStop 1.5
                    }
                    device [
                      PositionSensor {
                        name "RBL1_position sensor"
                      }
                      RotationalMotor {
                        name "RBL1_rotational motor"
                        maxTorque 2000
                      }
                    ]
                    endPoint Solid {
                      translation -4.351715419125692e-06 -0.165068141475467 -0.11293412911001076
                      rotation 0.9999999999961131 8.239031534879107e-07 -2.663597454360537e-06 0.6000203103315469
                      children [
                        DEF LEG_0_SHAPE Shape {
                          appearance PBRAppearance {
                            baseColor 1 1 0
                            roughness 1
                            metalness 0
                          }
                          geometry Capsule {
                            height 0.4
                            radius 0.02
                          }
                        }
                        Transform {
                          translation 0 -0.2 0
                          children [
                            DEF RB_LEG_L2 HingeJoint {
                              jointParameters HingeJointParameters {
                                position -1.28
                                minStop -2.2
                                maxStop -0.2
                              }
                              device [
                                PositionSensor {
                                  name "RBL2_position sensor"
                                }
                                RotationalMotor {
                                  name "RBL2_rotational motor"
                                  maxTorque 2000
                                }
                              ]
                              endPoint Solid {
                                translation 0 -0.057343041926416365 0.19160317205793076
                                rotation -1 0 0 1.2799999999999998
                                children [
                                  DEF LEG_1_SHAPE Shape {
                                    appearance PBRAppearance {
                                    }
                                    geometry Capsule {
                                      height 0.4
                                      radius 0.02
                                    }
                                  }
                                  TouchSensor {
                                    translation 1.3145040611561853e-13 -0.20000007730084096 -6.04002471094045e-08
                                    rotation -0.9999999999999227 -1.6391277313228361e-07 -3.5762786865225513e-07 -4.440892098501727e-16
                                    children [
                                      DEF TC_SENSOR Shape {
                                        appearance PBRAppearance {
                                        }
                                        geometry Sphere {
                                          radius 0.05
                                        }
                                      }
                                    ]
                                    name "RB_touch sensor"
                                    boundingObject USE TC_SENSOR
                                    physics Physics {
                                      density -1
                                      mass 0.2
                                    }
                                  }
                                ]
                                boundingObject USE LEG_1_SHAPE
                                physics Physics {
                                  density -1
                                  mass 4
                                }
                              }
                            }
                          ]
                        }
                      ]
                      boundingObject USE LEG_0_SHAPE
                      physics Physics {
                        density -1
                        mass 4
                      }
                    }
                  }
                ]
              }
            ]
            boundingObject USE L0_SHAPE
            physics Physics {
            }
          }
        }
      ]
    }
    DEF RF_LEG_POS Transform {
      translation -0.24 0 0.3
      children [
        DEF RF_LEG_L0 HingeJoint {
          jointParameters HingeJointParameters {
            position 4.3100604842605623e-20
            axis 0 0 1
            minStop -0.8
            maxStop 0.8
          }
          device [
            PositionSensor {
              name "RFL0_position sensor"
            }
            RotationalMotor {
              name "RFL0_rotational motor"
              maxTorque 2000
            }
          ]
          endPoint Solid {
            translation -9.43781297335633e-07 4.375386999566633e-05 -7.975034025164973e-06
            rotation -0.9999999998781625 -1.1049181717228083e-05 1.1026804594720728e-05 1.5708265123318128
            children [
              DEF L0_SHAPE Shape {
                appearance PBRAppearance {
                }
                geometry Cylinder {
                  height 0.05
                  radius 0.02
                }
              }
              Transform {
                rotation 1 0 0 1.5707996938995747
                children [
                  DEF RF_LEG_L1 HingeJoint {
                    jointParameters HingeJointParameters {
                      position 0.6
                      minStop 0.2
                      maxStop 1.5
                    }
                    device [
                      PositionSensor {
                        name "RFL1_position sensor"
                      }
                      RotationalMotor {
                        name "RFL1_rotational motor"
                        maxTorque 2000
                      }
                    ]
                    endPoint Solid {
                      translation -4.351715419097954e-06 -0.16506814147546214 -0.11293412911000718
                      rotation 0.9999999999961131 8.239108609594318e-07 -2.663622371858706e-06 0.6000203105926765
                      children [
                        DEF LEG_0_SHAPE Shape {
                          appearance PBRAppearance {
                            baseColor 1 1 0
                            roughness 1
                            metalness 0
                          }
                          geometry Capsule {
                            height 0.4
                            radius 0.02
                          }
                        }
                        Transform {
                          translation 0 -0.2 0
                          children [
                            DEF RF_LEG_L2 HingeJoint {
                              jointParameters HingeJointParameters {
                                position -1.28
                                minStop -2.2
                                maxStop -0.2
                              }
                              device [
                                PositionSensor {
                                  name "RFL2_position sensor"
                                }
                                RotationalMotor {
                                  name "RFL2_rotational motor"
                                  maxTorque 2000
                                }
                              ]
                              endPoint Solid {
                                translation 2.775557561563345e-17 -0.05734304192641826 0.19160317205793656
                                rotation -1 0 0 1.2799999999999998
                                children [
                                  DEF LEG_1_SHAPE Shape {
                                    appearance PBRAppearance {
                                    }
                                    geometry Capsule {
                                      height 0.4
                                      radius 0.02
                                    }
                                  }
                                  TouchSensor {
                                    translation 1.3145040611561853e-13 -0.20000007730084113 -6.040024708164893e-08
                                    rotation -0.9999999999990478 1.3709068298328347e-06 -1.5894571940090838e-07 -3.3306690738782627e-16
                                    children [
                                      DEF TC_SENSOR Shape {
                                        appearance PBRAppearance {
                                        }
                                        geometry Sphere {
                                          radius 0.05
                                        }
                                      }
                                    ]
                                    name "RF_touch sensor"
                                    boundingObject USE TC_SENSOR
                                    physics Physics {
                                      density -1
                                      mass 0.2
                                    }
                                  }
                                ]
                                boundingObject USE LEG_1_SHAPE
                                physics Physics {
                                  density -1
                                  mass 4
                                }
                              }
                            }
                          ]
                        }
                      ]
                      boundingObject USE LEG_0_SHAPE
                      physics Physics {
                        density -1
                        mass 4
                      }
                    }
                  }
                ]
              }
            ]
            name "solid(3)"
            boundingObject USE L0_SHAPE
            physics Physics {
            }
          }
        }
      ]
    }
    Solid {
      translation 0 0.15 0
      children [
        DEF frame Group {
          children [
            Transform {
              translation 1 -0.5 0
              children [
                Shape {
                  appearance PBRAppearance {
                  }
                  geometry Capsule {
                    height 0.5
                    radius 0.05
                  }
                }
              ]
            }
            Transform {
              translation -1 -0.5 0
              children [
                Shape {
                  appearance PBRAppearance {
                  }
                  geometry Capsule {
                    height 0.5
                    radius 0.05
                  }
                }
              ]
            }
            Transform {
              translation 0 -0.5 -1
              children [
                Shape {
                  appearance PBRAppearance {
                  }
                  geometry Capsule {
                    height 0.5
                    radius 0.05
                  }
                }
              ]
            }
            Transform {
              translation 0 -0.5 1
              children [
                Shape {
                  appearance PBRAppearance {
                  }
                  geometry Capsule {
                    height 0.5
                    radius 0.05
                  }
                }
              ]
            }
          ]
        }
      ]
      name "solid(1)"
    }
  ]
  boundingObject USE BODY_SHAPE
  physics Physics {
    density -1
    mass 50
  }
  controller "my_controller"
}
DEF SLOPE_PATH Solid {
  translation -8.24 0 6.64
  children [
    DEF SLOPE_GROUP Group {
      children [
        Transform {
          translation 0 0.207058 0.772743
          rotation 1 0 0 -0.2617996938995747
          children [
            Shape {
              appearance DEF APPERANCE PBRAppearance {
                baseColor 0.929412 0.992157 1
                roughness 1
                metalness 0
              }
              geometry DEF PATH Box {
                size 1.5 0.1 2
              }
            }
          ]
        }
        Transform {
          translation 0 0.47 2.73
          children [
            Shape {
              appearance USE APPERANCE
              geometry USE PATH
            }
          ]
        }
        Transform {
          translation 0 0.210114 4.67684
          rotation -1 0 0 -0.2617996938995747
          children [
            Shape {
              appearance USE APPERANCE
              geometry USE PATH
            }
          ]
        }
      ]
    }
  ]
  name "solid(1)"
  boundingObject USE SLOPE_GROUP
}
DEF SLOPE_PATH Solid {
  translation 5.3343 -1.77636e-14 5.9582
  rotation 0 1 0 -1.5707953071795862
  children [
    DEF SLOPE_GROUP Group {
      children [
        Transform {
          translation 0 0.610201 0.563372
          rotation 1 0 0 -0.3926996938995747
          children [
            Shape {
              appearance DEF APPERANCE PBRAppearance {
                baseColor 0.929412 0.992157 1
                roughness 1
                metalness 0
              }
              geometry DEF PATH Box {
                size 1.5 0.1 5
              }
            }
          ]
        }
        Transform {
          translation 0 1.56 5.36
          children [
            Shape {
              appearance USE APPERANCE
              geometry USE PATH
            }
          ]
        }
        Transform {
          translation 0 0.598708 10.1076
          rotation -1 0 0 -0.3926996938995747
          children [
            Shape {
              appearance USE APPERANCE
              geometry USE PATH
            }
          ]
        }
      ]
    }
  ]
  name "solid(2)"
  boundingObject USE SLOPE_GROUP
}
Solid {
  translation 0 1.77 -10.61
  children [
    HingeJoint {
      jointParameters HingeJointParameters {
        position -1.5
        axis 0 0 1
        minStop -1.5
        maxStop 1.5
      }
      endPoint Solid {
        translation -0.99749498660404 -0.070737201667703 0
        rotation 0 0 -1 1.5
        children [
          Shape {
            appearance USE APPERANCE
            geometry Sphere {
              radius 0.2
            }
          }
          Transform {
            translation 0 0.5 0
            children [
              Shape {
                appearance USE APPERANCE
                geometry Cylinder {
                  height 1
                  radius 0.03
                }
              }
            ]
          }
        ]
        boundingObject Sphere {
          radius 0.2
        }
        physics Physics {
          density -1
          mass 20
        }
      }
    }
  ]
}
DEF SLOPE_PATH Solid {
  translation 8.18 0 -9.24
  children [
    DEF SLOPE_GROUP Group {
      children [
        Transform {
          translation 0 0.610201 0.563372
          rotation 1 0 0 -0.26180030610042526
          children [
            Shape {
              appearance DEF APPERANCE PBRAppearance {
                baseColor 0.929412 0.992157 1
                roughness 1
                metalness 0
              }
              geometry DEF PATH Box {
                size 1.5 0.1 5
              }
            }
          ]
        }
        Transform {
          translation 0 1.25 5.44
          children [
            Shape {
              appearance USE APPERANCE
              geometry USE PATH
            }
          ]
        }
        Transform {
          translation 0 0.592256 10.3323
          rotation -1 0 0 -0.26180030610042526
          children [
            Shape {
              appearance USE APPERANCE
              geometry USE PATH
            }
          ]
        }
      ]
    }
  ]
  name "solid(4)"
  boundingObject USE SLOPE_GROUP
}
